Workbook

Sheet Armes
A1: Arme | B1: Code | C1: Catégorie | D1: Munition | E1: Poids (kg) | F1: Où l'acheter | G1: Prix
A2: Batte de baseball | B2: WEAPON_BAT | C2: Arme blanche | D2: — | E2: 1.13 | F2: Ammu-Nation 100 $ (sans permis) | G2: 100
A3: Bouteille cassée | B3: WEAPON_BOTTLE | C3: Arme blanche | D3: — | E3: 0.35 | F3: Non vendu (saisie, police, staff)
A4: Club de golf | B4: WEAPON_GOLFCLUB | C4: Arme blanche | D4: — | E4: 0.33 | F4: Non vendu (saisie, police, staff)
A5: Clé à molette | B5: WEAPON_WRENCH | C5: Arme blanche | D5: — | E5: 2.5 | F5: Non vendu (saisie, police, staff)
A6: Couteau | B6: WEAPON_KNIFE | C6: Arme blanche | D6: — | E6: 0.3 | F6: Ammu-Nation 200 $ (sans permis) | G6: 200
A7: Couteau à cran d'arrêt | B7: WEAPON_SWITCHBLADE | C7: Arme blanche | D7: — | E7: 0.3 | F7: Non vendu (saisie, police, staff)
A8: Dague | B8: WEAPON_DAGGER | C8: Arme blanche | D8: — | E8: 0.8 | F8: Non vendu (saisie, police, staff)
A9: Hache de combat | B9: WEAPON_BATTLEAXE | C9: Arme blanche | D9: — | E9: 6.5 | F9: Non vendu (saisie, police, staff)
A10: Hachette | B10: WEAPON_HATCHET | C10: Arme blanche | D10: — | E10: 1 | F10: Non vendu (saisie, police, staff)
A11: Hachette en pierre | B11: WEAPON_STONE_HATCHET | C11: Arme blanche | D11: — | E11: 0.8 | F11: Non vendu (saisie, police, staff)
A12: Lampe torche | B12: WEAPON_FLASHLIGHT | C12: Arme blanche | D12: — | E12: 0.12 | F12: Ammu-Nation 80 $ (sans permis) | G12: 80
A13: Machette | B13: WEAPON_MACHETE | C13: Arme blanche | D13: — | E13: 1 | F13: Non vendu (saisie, police, staff)
A14: Marteau | B14: WEAPON_HAMMER | C14: Arme blanche | D14: — | E14: 1.2 | F14: Non vendu (saisie, police, staff)
A15: Matraque | B15: WEAPON_NIGHTSTICK | C15: Arme blanche | D15: — | E15: 1 | F15: Non vendu (saisie, police, staff)
A16: Pied-de-biche | B16: WEAPON_CROWBAR | C16: Arme blanche | D16: — | E16: 2.5 | F16: Non vendu (saisie, police, staff)
A17: Poing américain | B17: WEAPON_KNUCKLE | C17: Arme blanche | D17: — | E17: 0.3 | F17: Non vendu (saisie, police, staff)
A18: Queue de billard | B18: WEAPON_POOLCUE | C18: Arme blanche | D18: — | E18: 0.15 | F18: Non vendu (saisie, police, staff)
A19: Sucre d'orge | B19: WEAPON_CANDYCANE | C19: Arme blanche | D19: — | E19: 0.09 | F19: Non vendu (saisie, police, staff)
A20: Canon électromagnétique | B20: WEAPON_RAILGUN | C20: Arme lourde | D20: Charge électromagnétique | E20: 3.57 | F20: Non vendu (saisie, police, staff)
A21: Lance-feux d'artifice | B21: WEAPON_FIREWORK | C21: Arme lourde | D21: Fusée de feu d'artifice | E21: 1 | F21: Non vendu (saisie, police, staff)
A22: Lance-grenades | B22: WEAPON_GRENADELAUNCHER | C22: Arme lourde | D22: Grenade 40 mm | E22: 6.5 | F22: Non vendu (saisie, police, staff)
A23: Lance-grenades compact | B23: WEAPON_COMPACTLAUNCHER | C23: Arme lourde | D23: Grenade 40 mm | E23: 2.5 | F23: Non vendu (saisie, police, staff)
A24: Lance-missiles | B24: WEAPON_HOMINGLAUNCHER | C24: Arme lourde | D24: Roquette | E24: 10 | F24: Non vendu (saisie, police, staff)
... A52: Fusil de combat | B52: WEAPON_COMBATSHOTGUN | C52: Fusil à pompe | D52: Cartouches calibre 12 | E52: 4.4 | F52: Non vendu (saisie, police, staff)
A53: Fusil à canon scié | B53: WEAPON_SAWNOFFSHOTGUN | C53: Fusil à pompe | D53: Cartouches calibre 12 | E53: 2.38 | F53: Marché noir 14 000 $ sale, stock 3/jour · gang seulement | G53: 14000
A54: Fusil à double canon | B54: WEAPON_DBSHOTGUN | C54: Fusil à pompe | D54: Cartouches calibre 12 | E54: 3.17 | F54: Non vendu (saisie, police, staff)
A55: Fusil à pompe | B55: WEAPON_PUMPSHOTGUN | C55: Fusil à pompe | D55: Cartouches calibre 12 | E55: 3.4 | F55: Ammu-Nation 5 500 $ (sans permis) | G55: 5500
A56: Fusil à pompe automatique | B56: WEAPON_AUTOSHOTGUN | C56: Fusil à pompe | D56: Cartouches calibre 12 | E56: 4.4 | F56: Non vendu (saisie, police, staff)
A57: Fusil à pompe bullpup | B57: WEAPON_BULLPUPSHOTGUN | C57: Fusil à pompe | D57: Cartouches calibre 12 | E57: 3.1 | F57: Non vendu (saisie, police, staff)
A58: Fusil à pompe d'assaut | B58: WEAPON_ASSAULTSHOTGUN | C58: Fusil à pompe | D58: Cartouches calibre 12 | E58: 5.2 | F58: Non vendu (saisie, police, staff)
A59: Fusil à pompe lourd | B59: WEAPON_HEAVYSHOTGUN | C59: Fusil à pompe | D59: Cartouches calibre 12 | E59: 3.6 | F59: Non vendu (saisie, police, staff)
A60: Mousquet | B60: WEAPON_MUSKET | C60: Fusil à pompe | D60: Balle de mousquet | E60: 4.5 | F60: Ammu-Nation 1 500 $ (sans permis) | G60: 1500
A61: Fusil à pompe Mk II | B61: WEAPON_PUMPSHOTGUN_MK2 | C61: Fusil à pompe (Mk II) | D61: Cartouches calibre 12 | E61: 3.2 | F61: Non vendu (saisie, police, staff)
A62: Mitraillette Gusenberg | B62: WEAPON_GUSENBERG | C62: Mitrailleuse | D62: Munitions .45 | E62: 4.9 | F62: Non vendu (saisie, police, staff)
A63: Mitrailleuse | B63: WEAPON_MG | C63: Mitrailleuse | D63: Munitions 7,62 | E63: 9 | F63: Non vendu (saisie, police, staff)
A64: Mitrailleuse de combat | B64: WEAPON_COMBATMG | C64: Mitrailleuse | D64: Munitions 5,56 | E64: 7.5 | F64: Non vendu (saisie, police, staff)
A65: Mitrailleuse de combat Mk II | B65: WEAPON_COMBATMG_MK2 | C65: Mitrailleuse (Mk II) | D65: Munitions 7,62 | E65: 8 | F65: Non vendu (saisie, police, staff)
A66: Bidon d'engrais | B66: WEAPON_FERTILIZERCAN | C66: Outil | D66: — | E66: 12 | F66: Non vendu (saisie, police, staff)
A67: Bidon de produit dangereux | B67: WEAPON_HAZARDCAN | C67: Outil | D67: — | E67: 12 | F67: Non vendu (saisie, police, staff)
...

Sheet Munitions
A1: Munition | B1: Code | C1: Armes qui l'utilisent | D1: Poids (kg) | E1: Où l'acheter | F1: Prix
A2: Balle de mousquet | B2: ammo-musket | C2: Mousquet | D2: 0.04 | E2: Ammu-Nation 8 $ (permis de chasse) | F2: 8
A3: Cartouche de détresse | B3: ammo-flare | C3: Pistolet de détresse | D3: 0.04 | E3: Non vendu (saisie, police, staff)
A4: Cartouches calibre 12 | B4: ammo-shotgun | C4: Fusil de combat, Fusil à canon scié, Fusil à double canon, Fusil à pompe, Fusil à pompe Mk II, Fusil à pompe automatique, Fusil à pompe bullpup, Fusil à pompe d'assaut, Fusil à pompe lourd | D4: 0.04 | E4: Ammu-Nation 12 $ (permis de port d'arme) · Marché noir 300 $ sale, stock 30/jour | F4: 12
A5: Charge IEM | B5: ammo-emp | C5: Lanceur IEM compact | D5: 0.4 | E5: Non vendu (saisie, police, staff)
A6: Charge laser | B6: ammo-laser | C6: Carabine atomiseur, Minigun atomiseur | D6: 0 | E6: Non vendu (saisie, police, staff)
A7: Charge électromagnétique | B7: ammo-railgun | C7: Canon électromagnétique, Canon électromagnétique XM3 | D7: 0.15 | E7: Non vendu (saisie, police, staff)
A8: Fusée de feu d'artifice | B8: ammo-firework | C8: Lance-feux d'artifice | D8: 0.2 | E8: Non vendu (saisie, police, staff)
A9: Grenade 40 mm | B9: ammo-grenade | C9: Lance-grenades, Lance-grenades compact | D9: 0.4 | E9: Non vendu (saisie, police, staff)
A10: Munitions .22 | B10: ammo-22 | C10: Pistolet de précision | D10: 0 | E10: Non vendu (saisie, police, staff)
A11: Munitions .38 | B11: ammo-38 | C11: Revolver double action | D11: 0.01 | E11: Non vendu (saisie, police, staff)
A12: Munitions .44 Magnum | B12: ammo-44 | C12: Revolver, Revolver Mk II, Revolver de la Marine | D12: 0.02 | E12: Non vendu (saisie, police, staff)
A13: Munitions .45 | B13: ammo-45 | C13: Micro-mitraillette, Mitraillette Gusenberg, Pistolet de poche, Pistolet de poche Mk II, Pistolet lourd | D13: 0.01 | E13: Ammu-Nation 7 $ (permis de port d'arme) · Marché noir 260 $ sale, stock 40/jour | F13: 7
A14: Munitions .50 | B14: ammo-50 | C14: Pistolet .50 | D14: 0.04 | E14: Non vendu (saisie, police, staff)
A15: Munitions .50 BMG | B15: ammo-heavysniper | C15: Fusil de précision lourd, Fusil de précision lourd Mk II | D15: 0.05 | E15: Non vendu (saisie, police, staff)
A16: Munitions 5,56 | B16: ammo-rifle | C16: Carabine, Carabine Mk II, Carabine spéciale, Carabine spéciale Mk II, Fusil avancé, Fusil bullpup, Fusil bullpup Mk II, Fusil lourd, Fusil militaire, Fusil tactique, Mitraillette d'assaut, Mitrailleuse de combat | D16: 0 | E16: Marché noir 650 $ sale, stock 25/jour | F16: 650
A17: Munitions 7,62 | B17: ammo-rifle2 | C17: Fusil compact, Fusil d'assaut, Fusil d'assaut Mk II, Fusil de combat, Minigun, Mitrailleuse, Mitrailleuse de combat Mk II | D17: 0.01 | E17: Marché noir 750 $ sale, stock 20/jour | F17: 750
A18: Munitions 7,62 (précision) | B18: ammo-sniper | C18: Fusil de précision, Fusil de précision (chasse), Fusil de tireur d'élite, Fusil de tireur d'élite Mk II | D18: 0.01 | E18: Non vendu (saisie, police, staff)
A19: Munitions 9 mm | B19: ammo-9 | C19: Arme de défense personnelle, Mini mitraillette, Mitraillette, Mitraillette Mk II, Mitraillette tactique, Pistolet, Pistolet Mk II, Pistolet Perico, Pistolet WM 29, Pistolet automatique, Pistolet de combat, Pistolet en céramique, Pistolet vintage, Pistolet-mitrailleur | D19: 0.01 | E19: Ammu-Nation 6 $ (permis de port d'arme) · Marché noir 220 $ sale, stock 60/jour | F19: 6
A20: Roquette | B20: ammo-rocket | C20: Lance-missiles, Lance-roquettes | D20: 0.5 | E20: Non vendu (saisie, police, staff)
A22: Ammu-Nation : 120 munitions par jour et par personnage, permis de port d'arme exigé (gs_blackmarket Config.Legal).

Sheet Accessoires
A1: Accessoire | B1: Code | C1: Poids (kg) | D1: Où l'acheter | E1: Prix
A2: Canon lourd | B2: at_barrel | C2: 0.28 | D2: Non vendu (saisie, police, staff)
A3: Chargeur grande capacité (fusil à pompe) | B3: at_clip_extended_shotgun | C3: 0.28 | D3: Non vendu (saisie, police, staff)
A4: Chargeur grande capacité (fusil) | B4: at_clip_extended_rifle | C4: 0.28 | D4: Non vendu (saisie, police, staff)
A5: Chargeur grande capacité (mitraillette) | B5: at_clip_extended_smg | C5: 0.28 | D5: Non vendu (saisie, police, staff)
A6: Chargeur grande capacité (mitrailleuse) | B6: at_clip_extended_mg | C6: 0.28 | D6: Non vendu (saisie, police, staff)
A7: Chargeur grande capacité (pistolet) | B7: at_clip_extended_pistol | C7: 0.28 | D7: Marché noir 3 000 $ sale, stock 6/jour | E7: 3000
A8: Chargeur grande capacité (précision) | B8: at_clip_extended_sniper | C8: 0.28 | D8: Non vendu (saisie, police, staff)
A9: Chargeur tambour (fusil à pompe) | B9: at_clip_drum_shotgun | C9: 0.28 | D9: Non vendu (saisie, police, staff)
A10: Chargeur tambour (fusil) | B10: at_clip_drum_rifle | C10: 0.28 | D10: Non vendu (saisie, police, staff)
A11: Chargeur tambour (mitraillette) | B11: at_clip_drum_smg | C11: 0.28 | D11: Non vendu (saisie, police, staff)
A12: Compensateur | B12: at_compensator | C12: 0.28 | D12: Non vendu (saisie, police, staff)
A13: Finition Ballas | B13: at_skin_ballas | C13: 0.05 | D13: Non vendu (saisie, police, staff)
A14: Finition Blagueurs | B14: at_skin_blagueurs | C14: 0.05 | D14: Non vendu (saisie, police, staff)
A15: Finition Boom | B15: at_skin_boom | C15: 0.05 | D15: Non vendu (saisie, police, staff)
A16: Finition Burger Shot | B16: at_skin_burgershot | C16: 0.05 | D16: Non vendu (saisie, police, staff)
A17: Finition Cluckin' Bell | B17: at_skin_cluckinbell | C17: 0.05 | D17: Non vendu (saisie, police, staff)
A18: Finition Fatal Incursion | B18: at_skin_fatalincursion | C18: 0.05 | D18: Non vendu (saisie, police, staff)
A19: Finition Hate | B19: at_skin_hate | C19: 0.05 | D19: Non vendu (saisie, police, staff)
... A60: Grande lunette | B60: at_scope_large | C60: 0.28 | D60: Non vendu (saisie, police, staff)
A61: Lampe tactique | B61: at_flashlight | C61: 0.12 | D61: Ammu-Nation 350 $ (permis de port d'arme) | E61: 350
A62: Lunette avancée | B62: at_scope_advanced | C62: 0.28 | D62: Non vendu (saisie, police, staff)
A63: Lunette moyenne | B63: at_scope_medium | C63: 0.28 | D63: Non vendu (saisie, police, staff)
A64: Lunette thermique | B64: at_scope_thermal | C64: 0.42 | D64: Non vendu (saisie, police, staff)
A65: Lunette à vision nocturne | B65: at_scope_nv | C65: 0.42 | D65: Non vendu (saisie, police, staff)
A66: Petite lunette | B66: at_scope_small | C66: 0.28 | D66: Non vendu (saisie, police, staff)
A67: Poignée | B67: at_grip | C67: 0.28 | D67: Non vendu (saisie, police, staff)
A68: Silencieux | B68: at_suppressor_light | C68: 0.28 | D68: Marché noir 8 000 $ sale, stock 4/jour | E68: 8000
A69: Silencieux tactique | B69: at_suppressor_heavy | C69: 0.28 | D69: Non vendu (saisie, police, staff)
A70: Viseur holographique | B70: at_scope_holo | C70: 0.28 | D70: Non vendu (saisie, police, staff)
A71: Viseur macro | B71: at_scope_macro | C71: 0.28 | D71: Non vendu (saisie, police, staff)

Sheet Résumé
A1: RoadLine RP · Armes, munitions et accessoires (résumé)
A3: Armes | B3: =COUNTA(Armes!B2:B109)
A4: Munitions | B4: =COUNTA(Munitions!B2:B20)
A5: Accessoires | B5: =COUNTA(Accessoires!B2:B71)
A6: Armes vendues à l'Ammu-Nation | B6: =COUNTIF(Armes!F2:F109,"Ammu-Nation*")
A7: Armes vendues au marché noir | B7: =COUNTIF(Armes!F2:F109,"*Marché noir*")
A8: Armes non vendues (saisie, police, staff) | B8: =COUNTIF(Armes!F2:F109,"Non vendu*")
A10: Arme blanche | B10: =COUNTIF(Armes!C2:C109,"Arme blanche")
A11: Arme lourde | B11: =COUNTIF(Armes!C2:C109,"Arme lourde")
A12: Autre | B12: =COUNTIF(Armes!C2:C109,"Autre")
A13: Fusil d'assaut | B13: =COUNTIF(Armes!C2:C109,"Fusil d'assaut")
A14: Fusil d'assaut (Mk II) | B14: =COUNTIF(Armes!C2:C109,"Fusil d'assaut (Mk II)")
A15: Fusil de précision | B15: =COUNTIF(Armes!C2:C109,"Fusil de précision")
A16: Fusil de précision (Mk II) | B16: =COUNTIF(Armes!C2:C109,"Fusil de précision (Mk II)")
A17: Fusil à pompe | B17: =COUNTIF(Armes!C2:C109,"Fusil à pompe")
A18: Fusil à pompe (Mk II) | B18: =COUNTIF(Armes!C2:C109,"Fusil à pompe (Mk II)")
A19: Mitrailleuse | B19: =COUNTIF(Armes!C2:C109,"Mitrailleuse")
A20: Mitrailleuse (Mk II) | B20: =COUNTIF(Armes!C2:C109,"Mitrailleuse (Mk II)")
A21: Outil | B21: =COUNTIF(Armes!C2:C109,"Outil")
A22: Pistolet | B22: =COUNTIF(Armes!C2:C109,"Pistolet")
A23: Pistolet (Mk II) | B23: =COUNTIF(Armes!C2:C109,"Pistolet (Mk II)")
A24: Pistolet-mitrailleur | B24: =COUNTIF(Armes!C2:C109,"Pistolet-mitrailleur")
A25: Pistolet-mitrailleur (Mk II) | B25: =COUNTIF(Armes!C2:C109,"Pistolet-mitrailleur (Mk II)")
A26: Projectile | B26: =COUNTIF(Armes!C2:C109,"Projectile")
A28: Les chiffres de cette feuille sont des formules (COUNTIF / SUMIF…) calculées sur la feuille de données : ils se mettent à jour si tu modifies le tableau.
