Workbook

Sheet Véhicules
A1: Boutique | B1: Catégorie | C1: Marque | D1: Véhicule | E1: Modèle (spawn) | F1: Prix
A2: Aéroport | B2: helicopters | C2: Nagasaki | D2: Havok | E2: havok | F2: 380000
A3: Aéroport | B3: helicopters | C3: Western | D3: Maverick | E3: maverick | F3: 950000
A4: Aéroport | B4: helicopters | C4: Maibatsu | D4: Frogger | E4: frogger | F4: 1100000
A5: Aéroport | B5: helicopters | C5: Buckingham | D5: Conada | E5: conada | F5: 1350000
A6: Aéroport | B6: helicopters | C6: Buckingham | D6: SuperVolito | E6: supervolito | F6: 1600000
A7: Aéroport | B7: helicopters | C7: Buckingham | D7: Swift | E7: swift | F7: 1800000
A8: Aéroport | B8: helicopters | C8: Buckingham | D8: SuperVolito Carbon | E8: supervolito2 | F8: 1900000
A9: Aéroport | B9: helicopters | C9: Buckingham | D9: Swift Deluxe | E9: swift2 | F9: 2400000
A10: Aéroport | B10: helicopters | C10: Buckingham | D10: Volatus | E10: volatus | F10: 2900000
A11: Aéroport | B11: helicopters | D11: Sea Sparrow | E11: seasparrow | F11: 6293144
A12: Aéroport | B12: helicopters | C12: Maibatsu | D12: Frogger (Trevor Philips Enterprises) | E12: frogger2 | F12: 6367865
A13: Aéroport | B13: helicopters | C13: Nagasaki | D13: Buzzard | E13: buzzard2 | F13: 6462758
A14: Aéroport | B14: helicopters | D14: Sparrow | E14: seasparrow2 | F14: 7760028
A15: Aéroport | B15: helicopters | D15: Sparrow (Prop) | E15: seasparrow3 | F15: 7760028
A16: Aéroport | B16: planes | C16: Nagasaki | D16: Ultralight | E16: microlight | F16: 45000
A17: Aéroport | B17: planes | C17: Western | D17: Duster | E17: duster | F17: 220000
A18: Aéroport | B18: planes | C18: Western Company | D18: Mallard | E18: stunt | F18: 260000
A19: Aéroport | B19: planes | C19: Western | D19: Cuban 800 | E19: cuban800 | F19: 280000
A20: Aéroport | B20: planes | C20: JoBuilt | D20: Mammatus | E20: mammatus | F20: 320000
A21: Aéroport | B21: planes | C21: Mammoth | D21: Dodo | E21: dodo | F21: 380000
A22: Aéroport | B22: planes | C22: Western | D22: Seabreeze | E22: seabreeze | F22: 480000
A23: Aéroport | B23: planes | C23: JoBuilt | D23: Velum | E23: velum | F23: 520000
A24: Aéroport | B24: planes | C24: Buckingham | D24: Howard NX-25 | E24: howard | F24: 650000
A25: Aéroport | B25: planes | C25: Buckingham | D25: Alpha-Z1 | E25: alphaz1 | F25: 750000
A26: Aéroport | B26: planes | C26: Buckingham | D26: Vestra | E26: vestra | F26: 950000
A27: Aéroport | B27: planes | C27: JoBuilt | D27: Velum | E27: velum2 | F27: 1439638
... A71: Concession | B71: cycles | C71: PED | D71: Scorcher | E71: scorcher | F71: 2782
A72: Concession | B72: cycles | D72: Fixter | E72: fixter | F72: 2835
A73: Concession | B73: cycles | D73: Endurex Race Bike | E73: tribike2 | F73: 3622
A74: Concession | B74: cycles | D74: Tri-Cycles Race Bike | E74: tribike3 | F74: 3622
A75: Concession | B75: cycles | D75: Whippet Race Bike | E75: tribike | F75: 3622
A76: Concession | B76: motorcycles | C76: Pegassi | D76: Faggio Sport | E76: faggio2 | F76: 12263
A77: Concession | B77: motorcycles | C77: Pegassi | D77: Faggio Mod | E77: faggio3 | F77: 14291
A78: Concession | B78: motorcycles | C78: Pegassi | D78: Faggio Sport | E78: faggio | F78: 14728
A79: Concession | B79: motorcycles | C79: Western | D79: Rat Bike | E79: ratbike | F79: 19441
A80: Concession | B80: motorcycles | C80: Western | D80: Wolfsbane | E80: wolfsbane | F80: 19441
A81: Concession | B81: motorcycles | C81: Western | D81: Bagger | E81: bagger | F81: 19934
A82: Concession | B82: motorcycles | C82: Maibatsu | D82: Sanchez | E82: sanchez2 | F82: 20686
A83: Concession | B83: motorcycles | C83: Maibatsu | D83: Sanchez (livery) | E83: sanchez | F83: 20686
...

Sheet Résumé
A1: RoadLine RP · Catalogue des véhicules (résumé)
A3: Véhicules en vente | B3: =COUNTA('Véhicules'!E2:E601)
A4: Concession | B4: =COUNTIF('Véhicules'!A2:A601,"Concession")
A5: Aéroport | B5: =COUNTIF('Véhicules'!A2:A601,"Aéroport")
A6: Marina | B6: =COUNTIF('Véhicules'!A2:A601,"Marina")
A7: Prix le plus bas | B7: =MIN('Véhicules'!F2:F601)
A8: Prix le plus haut | B8: =MAX('Véhicules'!F2:F601)
A9: Prix moyen | B9: =AVERAGE('Véhicules'!F2:F601)
A10: Valeur totale du catalogue | B10: =SUM('Véhicules'!F2:F601)
A12: Catégorie « boats » | B12: =COUNTIF('Véhicules'!B2:B601,"boats")
A13: Catégorie « compacts » | B13: =COUNTIF('Véhicules'!B2:B601,"compacts")
A14: Catégorie « coupes » | B14: =COUNTIF('Véhicules'!B2:B601,"coupes")
A15: Catégorie « cycles » | B15: =COUNTIF('Véhicules'!B2:B601,"cycles")
A16: Catégorie « helicopters » | B16: =COUNTIF('Véhicules'!B2:B601,"helicopters")
A17: Catégorie « motorcycles » | B17: =COUNTIF('Véhicules'!B2:B601,"motorcycles")
A18: Catégorie « muscle » | B18: =COUNTIF('Véhicules'!B2:B601,"muscle")
A19: Catégorie « offroad » | B19: =COUNTIF('Véhicules'!B2:B601,"offroad")
A20: Catégorie « planes » | B20: =COUNTIF('Véhicules'!B2:B601,"planes")
A21: Catégorie « sedans » | B21: =COUNTIF('Véhicules'!B2:B601,"sedans")
A22: Catégorie « sports » | B22: =COUNTIF('Véhicules'!B2:B601,"sports")
A23: Catégorie « sportsclassics » | B23: =COUNTIF('Véhicules'!B2:B601,"sportsclassics")
A24: Catégorie « super » | B24: =COUNTIF('Véhicules'!B2:B601,"super")
A25: Catégorie « suvs » | B25: =COUNTIF('Véhicules'!B2:B601,"suvs")
A26: Catégorie « vans » | B26: =COUNTIF('Véhicules'!B2:B601,"vans")
A28: Les chiffres de cette feuille sont des formules (COUNTIF / SUMIF…) calculées sur la feuille de données : ils se mettent à jour si tu modifies le tableau.
